2021-05-01 06:10:33,869 INFO    MainThread:76 [wandb_setup.py:_flush():69] setting env: {}
2021-05-01 06:10:33,869 INFO    MainThread:76 [wandb_setup.py:_flush():69] setting login settings: {}
2021-05-01 06:10:33,869 INFO    MainThread:76 [wandb_setup.py:_flush():69] setting login settings: {'api_key': '7026e8a4491e2f9361b138dbc974e7f71b74a6c2'}
2021-05-01 06:10:33,870 INFO    MainThread:76 [wandb_setup.py:_flush():69] setting login settings: {}
2021-05-01 06:10:33,870 INFO    MainThread:76 [wandb_init.py:_log_setup():336] Logging user logs to /home/runner/basiclstm/wandb/run-20210501_061033-26dmr9w9/logs/debug.log
2021-05-01 06:10:33,870 INFO    MainThread:76 [wandb_init.py:_log_setup():337] Logging internal logs to /home/runner/basiclstm/wandb/run-20210501_061033-26dmr9w9/logs/debug-internal.log
2021-05-01 06:10:33,870 INFO    MainThread:76 [wandb_init.py:init():369] calling init triggers
2021-05-01 06:10:33,870 INFO    MainThread:76 [wandb_init.py:init():374] wandb.init called with sweep_config: {}
config: {'model': 'Model', 'dataset_cls': 'ManyThings', 'net_fn': 'nn_lstm1', 'net_args': {'decay': 1e-06, 'dropout': 0.2, 'epochs': 3, 'latent_dim': 300, 'learn-rate': 0.01, 'momentum': 0.9, 'hidden_layer_size': 300, 'learn_rate': 0.01}, 'dataset_args': None}
2021-05-01 06:10:33,871 INFO    MainThread:76 [wandb_init.py:init():418] starting backend
2021-05-01 06:10:33,871 INFO    MainThread:76 [backend.py:_multiprocessing_setup():69] multiprocessing start_methods=fork,spawn,forkserver, using: spawn
2021-05-01 06:10:33,988 INFO    MainThread:76 [backend.py:ensure_launched():123] starting backend process...
2021-05-01 06:10:33,996 INFO    MainThread:76 [backend.py:ensure_launched():127] started backend process with pid: 98
2021-05-01 06:10:33,997 INFO    MainThread:76 [wandb_init.py:init():423] backend started and connected
2021-05-01 06:10:34,001 INFO    MainThread:76 [wandb_init.py:init():465] updated telemetry
2021-05-01 06:10:34,001 INFO    MainThread:76 [wandb_init.py:init():484] communicating current version
2021-05-01 06:10:34,936 INFO    MainThread:76 [wandb_init.py:init():489] got version response 
2021-05-01 06:10:34,936 INFO    MainThread:76 [wandb_init.py:init():497] communicating run to backend with 30 second timeout
2021-05-01 06:11:02,609 ERROR   Thread-1  :76 [retry.py:__call__():114] Retry attempt failed:
Traceback (most recent call last):
  File "/opt/virtualenvs/python3/lib/python3.8/site-packages/urllib3/connectionpool.py", line 445, in _make_request
    six.raise_from(e, None)
  File "<string>", line 3, in raise_from
  File "/opt/virtualenvs/python3/lib/python3.8/site-packages/urllib3/connectionpool.py", line 440, in _make_request
    httplib_response = conn.getresponse()
  File "/usr/lib/python3.8/http/client.py", line 1344, in getresponse
    response.begin()
  File "/usr/lib/python3.8/http/client.py", line 307, in begin
    version, status, reason = self._read_status()
  File "/usr/lib/python3.8/http/client.py", line 268, in _read_status
    line = str(self.fp.readline(_MAXLINE + 1), "iso-8859-1")
  File "/usr/lib/python3.8/socket.py", line 669, in readinto
    return self._sock.recv_into(b)
  File "/usr/lib/python3.8/ssl.py", line 1241, in recv_into
    return self.read(nbytes, buffer)
  File "/usr/lib/python3.8/ssl.py", line 1099, in read
    return self._sslobj.read(len, buffer)
socket.timeout: The read operation timed out

During handling of the above exception, another exception occurred:

Traceback (most recent call last):
  File "/opt/virtualenvs/python3/lib/python3.8/site-packages/requests/adapters.py", line 439, in send
    resp = conn.urlopen(
  File "/opt/virtualenvs/python3/lib/python3.8/site-packages/urllib3/connectionpool.py", line 755, in urlopen
    retries = retries.increment(
  File "/opt/virtualenvs/python3/lib/python3.8/site-packages/urllib3/util/retry.py", line 532, in increment
    raise six.reraise(type(error), error, _stacktrace)
  File "/opt/virtualenvs/python3/lib/python3.8/site-packages/urllib3/packages/six.py", line 735, in reraise
    raise value
  File "/opt/virtualenvs/python3/lib/python3.8/site-packages/urllib3/connectionpool.py", line 699, in urlopen
    httplib_response = self._make_request(
  File "/opt/virtualenvs/python3/lib/python3.8/site-packages/urllib3/connectionpool.py", line 447, in _make_request
    self._raise_timeout(err=e, url=url, timeout_value=read_timeout)
  File "/opt/virtualenvs/python3/lib/python3.8/site-packages/urllib3/connectionpool.py", line 336, in _raise_timeout
    raise ReadTimeoutError(
urllib3.exceptions.ReadTimeoutError: HTTPSConnectionPool(host='api.wandb.ai', port=443): Read timed out. (read timeout=10)

During handling of the above exception, another exception occurred:

Traceback (most recent call last):
  File "/opt/virtualenvs/python3/lib/python3.8/site-packages/wandb/old/retry.py", line 100, in __call__
    result = self._call_fn(*args, **kwargs)
  File "/opt/virtualenvs/python3/lib/python3.8/site-packages/wandb/sdk/internal/internal_api.py", line 127, in execute
    return self.client.execute(*args, **kwargs)
  File "/opt/virtualenvs/python3/lib/python3.8/site-packages/wandb/vendor/gql-0.2.0/gql/client.py", line 52, in execute
    result = self._get_result(document, *args, **kwargs)
  File "/opt/virtualenvs/python3/lib/python3.8/site-packages/wandb/vendor/gql-0.2.0/gql/client.py", line 60, in _get_result
    return self.transport.execute(document, *args, **kwargs)
  File "/opt/virtualenvs/python3/lib/python3.8/site-packages/wandb/vendor/gql-0.2.0/gql/transport/requests.py", line 38, in execute
    request = requests.post(self.url, **post_args)
  File "/opt/virtualenvs/python3/lib/python3.8/site-packages/requests/api.py", line 119, in post
    return request('post', url, data=data, json=json, **kwargs)
  File "/opt/virtualenvs/python3/lib/python3.8/site-packages/requests/api.py", line 61, in request
    return session.request(method=method, url=url, **kwargs)
  File "/opt/virtualenvs/python3/lib/python3.8/site-packages/requests/sessions.py", line 542, in request
    resp = self.send(prep, **send_kwargs)
  File "/opt/virtualenvs/python3/lib/python3.8/site-packages/requests/sessions.py", line 655, in send
    r = adapter.send(request, **kwargs)
  File "/opt/virtualenvs/python3/lib/python3.8/site-packages/requests/adapters.py", line 529, in send
    raise ReadTimeout(e, request=request)
requests.exceptions.ReadTimeout: HTTPSConnectionPool(host='api.wandb.ai', port=443): Read timed out. (read timeout=10)
2021-05-01 06:11:04,937 INFO    MainThread:76 [interface.py:_communicate_run():646] couldn't get run from backend
2021-05-01 06:11:04,937 ERROR   MainThread:76 [wandb_init.py:init():501] backend process timed out
2021-05-01 06:11:04,937 ERROR   MainThread:76 [wandb_init.py:init():510] encountered error: Error communicating with wandb process
try: wandb.init(settings=wandb.Settings(start_method='fork'))
or:  wandb.init(settings=wandb.Settings(start_method='thread'))
For more info see: https://docs.wandb.ai/library/init#init-start-error
2021-05-01 06:11:10,764 WARNING MainThread:76 [wandb_init.py:init():764] interrupted
Traceback (most recent call last):
  File "/opt/virtualenvs/python3/lib/python3.8/site-packages/wandb/sdk/wandb_init.py", line 744, in init
    run = wi.init()
  File "/opt/virtualenvs/python3/lib/python3.8/site-packages/wandb/sdk/wandb_init.py", line 513, in init
    backend.cleanup()
  File "/opt/virtualenvs/python3/lib/python3.8/site-packages/wandb/sdk/backend/backend.py", line 155, in cleanup
    self.wandb_process.join()
  File "/usr/lib/python3.8/multiprocessing/process.py", line 149, in join
    res = self._popen.wait(timeout)
  File "/usr/lib/python3.8/multiprocessing/popen_fork.py", line 47, in wait
    return self.poll(os.WNOHANG if timeout == 0.0 else 0)
  File "/usr/lib/python3.8/multiprocessing/popen_fork.py", line 27, in poll
    pid, sts = os.waitpid(self.pid, flag)
KeyboardInterrupt
